Workbook

Sheet README
A1: Misconception item bank – grades 7–9
A3: Purpose | B3: A tagged catalogue of documented mathematical misconceptions and errors, with one illustrative diagnostic item per misconception, for the JAES FinnMath-teaching App (quizzes, example homeworks, definition look-up tables).
A4: Created | B4: 20 September 2026, from the literature summary math_misconceptions_grades7-9_summary.docx and the bibliography math_misconceptions_grades7-9.bib (85 entries).
A5: Sheets | B5: Misconceptions = the catalogue (33 rows). Item bank template = where to write real items, linked to misconception IDs. Summary = counts by strand and evidence strength (formulas). Sources = references used, parsed from the .bib file.
A6: How to use | B6: 1) Filter the Misconceptions sheet by strand or evidence strength. 2) Copy a row's stem and distractor into the Item bank template as a starting point, then rewrite in Finnish and adapt numbers. 3) Fill the yellow column 'Finnish curriculum item' by mapping to your Finnish_math_curriculum document.
A7: Editable cells | B7: Yellow cells with blue text are for you to edit or fill. Everything else is reference content or a formula.
A8: Evidence strength – Strong | B8: Documented in several studies or one large-sample study, checked at abstract level in this project.
A9: Evidence strength – Moderate | B9: At least one empirical study or a review checked at abstract level; the exact item wording here is illustrative.
A10: Evidence strength – Limited | B10: Mentioned in a review, tied to a study only by title, recalled from the literature, or the item is not the study's own. Check the full text before relying on it.
A11: Important caveats | B11: Items were written for this project, not taken from the studies. The wrong answer shown is the most typical option, not a measured majority answer. Most evidence is from outside Finland. Finnish decimal comma is used in the items; keep it in translations. Evidence was read at abstract or excerpt level except the Finnish percentage study.
A12: Licences | B12: No third-party item text was copied. If you seed the bank from the Eedi Kaggle dataset or the Otero et al. (2024) benchmark, check their licences first.

Sheet Misconceptions
A1: ID | B1: Strand | C1: Topic | D1: Misconception | E1: Description | F1: Illustrative item (stem) | G1: Correct answer | H1: Typical wrong answer (distractor) | I1: Why students choose it | J1: Sample in key sources | K1: Evidence strength | L1: Source keys (see Sources sheet) | M1: Curriculum area | N1: Finnish curriculum item (fill in)
A2: ALG-01 | B2: Algebra | C2: Variables and letters | D2: Letter as object (label) | E2: A letter is read as a label for an object (apples, pears) instead of a number. | F2: Anna buys a apples at 5 cents each and p pears at 3 cents each. What does the expression 5a + 3p give? | G2: The total cost in cents. | H2: 5 apples and 3 pears. | I2: The letters are read as names of objects and the numbers as amounts of them. | J2: Year 7–8, Germany (N = 2,220); Years 7–10, Australia (24 schools) | K2: Strong | L2: kuchemann1981algebra; macgregor1997notation; klingbeil2025omnipresence | M2: Algebra and equations
A3: ALG-02 | B3: Algebra | C3: Variables and letters | D3: Different letters must differ in value | E3: Different letters are assumed to stand for different numbers. | F3: Can c + d = 10 be true when c and d have the same value? | G3: Yes: c = 5 and d = 5. | H3: No, different letters must stand for different numbers. | I3: A letter is treated as a fixed name for one number, so two letters cannot share a value. | J3: Described as a well-documented preconception in a 2026 German study (authors not verified) that cites Küchemann and MacGregor & Stacey | K3: Moderate | L3: kuchemann1981algebra; macgregor1997notation | M3: Algebra and equations
A4: ALG-03 | B4: Algebra | C4: Variables and letters | D4: Value from alphabet position | E4: The value of a letter is assumed from its place in the alphabet. | F4: n + 5 = 12. What is n? | G4: n = 7 | H4: n = 14, because n is the 14th letter. | I4: The letter is evaluated by position, not solved for. | J4: Mentioned as a documented numerical preconception in a 2026 German study (authors not verified) | K4: Limited | L4: kuchemann1981algebra | M4: Algebra and equations
A5: ALG-04 | B5: Algebra | C5: Expressions and notation | D5: Conjoining terms | E5: Terms are joined into a single term to 'finish' the expression. | F5: Simplify 3x + 8. | G5: 3x + 8 (it cannot be simplified further). | H5: 11x | I5: The '+' is read as a request to produce one answer, so numbers and letter terms are combined. | J5: Years 7–10, Australia (24 schools) | K5: Moderate | L5: macgregor1997notation; kuchemann1981algebra | M5: Algebra and equations
A6: ALG-05 | B6: Algebra | C6: Expressions and notation | D6: Juxtaposition read as place value | E6: In 2a the letter and number are read like digits in a numeral. | F6: If a = 5, what is the value of 2a? | G6: 10 | H6: 25 | I6: Analogy with place-value notation, where 25 means 2 tens and 5 ones. | J6: Years 7–10, Australia (24 schools); origins described as analogies with familiar symbol systems | K6: Moderate | L6: macgregor1997notation | M6: Algebra and equations
A7: ALG-06 | B7: Algebra | C7: Equal sign | D7: Operational reading of '=' | E7: '=' is read as 'the answer comes next' rather than 'both sides have the same value'. | F7: Fill in the box: 8 + 4 = □ + 5 | G7: 7 | H7: 12 (or 17). | I7: The student adds the numbers on the left and writes the result, ignoring the right side. | J7: Middle school, U.S.; many earlier studies | K7: Strong | L7: kieran1981equality; knuth2006equal | M7: Algebra and equations
A8: ALG-07 | B8: Algebra | C8: Solving equations | D8: Sign errors and one-sided operations | E8: Terms are moved without changing sign, or an operation is applied to only one side. | F8: Solve 3x + 5 = 20. | G8: x = 5 | H8: x = 25/3 (from 3x = 20 + 5). | I8: 'Moving' 5 across the equal sign without inverting the operation. | J8: Algebra I, U.S. (error analysis over the school year) | K8: Moderate | L8: booth2014persistent; kieran2007learning; bush2013prerequisite | M8: Algebra and equations
A9: ALG-08 | B9: Algebra | C9: Brackets and distribution | D9: Distributive law applied to one term | E9: A multiplier is applied to the first term in a bracket only ('linear extrapolation'). | F9: Expand 2(x + 3). | G9: 2x + 6 | H9: 2x + 3 | I9: A valid rule is extended to a new situation but applied partially. | J9: High-school algebra error models; middle-grade reviews | K9: Moderate | L9: matz1982process; bush2013prerequisite | M9: Algebra and equations
A10: ALG-09 | B10: Algebra | C10: Brackets and powers | D10: Square of a sum | E10: The power is distributed over addition. | F10: Expand (a + b)². | G10: a² + 2ab + b² | H10: a² + b² | I10: Distribution of the exponent over a sum, by analogy with (ab)² = a²b². | J10: High-school algebra error models; middle-grade reviews | K10: Moderate | L10: matz1982process; bush2013prerequisite | M10: Algebra and equations
A11: ALG-10 | B11: Algebra | C11: Translating word problems | D11: Reversal error | E11: The letters follow the order of words in the sentence. | F11: There are 6 times as many students (S) as professors (P). Which equation is correct? | G11: S = 6P | H11: 6S = P | I11: Word order is mapped directly to symbol order ('6 S ... P'). | J11: Students and professors problem; classic and replicated studies | K11: Strong | L11: clement1981translation; clement1982algebra | M11: Algebra and equations
A12: ALG-11 | B12: Algebra | C12: Negative numbers and the minus sign | D12: Minus sign not distributed | E12: The minus sign before a bracket is applied to the first term only. | F12: Simplify −(x − 3). | G12: −x + 3 | H12: −x − 3 | I12: The minus is read as belonging to x, not to the whole bracket. | J12: Interviews with 12 eighth-graders, Belgium | K12: Moderate | L12: vlassis2004minus | M12: Algebra and equations
A13: ALG-12 | B13: Algebra | C13: Negative numbers and the minus sign | D13: Subtraction of a negative number | E13: Natural-number rules about subtraction are carried over to negatives. | F13: Calculate 5 − (−2). | G13: 7 | H13: 3 | I13: 'Subtracting makes smaller' is applied without regard to the sign of the subtrahend. | J13: Related findings from interviews with 12 eighth-graders, Belgium (indirect) | K13: Limited | L13: vlassis2004minus | M13: Algebra and equations
... A34: PRB-02 | B34: Probability | C34: Comparing chances | D34: More black marbles means higher chance | E34: The absolute count is used instead of the proportion. | F34: Jar 1 has 6 black marbles out of 8. Jar 2 has 3 black marbles out of 4. Which jar gives the higher chance of drawing black? | G34: Both are equal (3/4). | H34: Jar 1, because it has more black marbles. | I34: An intuitive rule: more of one quantity (black marbles) means more of another (chance). | J34: Intuitive-rule studies (Israel and cross-cultural) | K34: Moderate | L34: tirosh1999intuitive; stavy2000how | M34: Probability and statistics

Sheet Summary
A1: Counts by strand and evidence strength
A3: Strand | B3: Strong | C3: Moderate | D3: Limited | E3: Total
A4: Algebra | B4: =COUNTIFS(Misconceptions!$B$2:$B$34,$A4,Misconceptions!$K$2:$K$34,B$3) -> 3 | C4: =COUNTIFS(Misconceptions!$B$2:$B$34,$A4,Misconceptions!$K$2:$K$34,C$3) -> 7 | D4: =COUNTIFS(Misconceptions!$B$2:$B$34,$A4,Misconceptions!$K$2:$K$34,D$3) -> 2 | E4: =SUM(B4:D4) -> 12
A5: Number | B5: =COUNTIFS(Misconceptions!$B$2:$B$34,$A5,Misconceptions!$K$2:$K$34,B$3) -> 5 | C5: =COUNTIFS(Misconceptions!$B$2:$B$34,$A5,Misconceptions!$K$2:$K$34,C$3) -> 2 | D5: =COUNTIFS(Misconceptions!$B$2:$B$34,$A5,Misconceptions!$K$2:$K$34,D$3) -> 1 | E5: =SUM(B5:D5) -> 8
A6: Proportion and geometry | B6: =COUNTIFS(Misconceptions!$B$2:$B$34,$A6,Misconceptions!$K$2:$K$34,B$3) -> 2 | C6: =COUNTIFS(Misconceptions!$B$2:$B$34,$A6,Misconceptions!$K$2:$K$34,C$3) -> 2 | D6: =COUNTIFS(Misconceptions!$B$2:$B$34,$A6,Misconceptions!$K$2:$K$34,D$3) -> 0 | E6: =SUM(B6:D6) -> 4
A7: Geometry | B7: =COUNTIFS(Misconceptions!$B$2:$B$34,$A7,Misconceptions!$K$2:$K$34,B$3) -> 0 | C7: =COUNTIFS(Misconceptions!$B$2:$B$34,$A7,Misconceptions!$K$2:$K$34,C$3) -> 2 | D7: =COUNTIFS(Misconceptions!$B$2:$B$34,$A7,Misconceptions!$K$2:$K$34,D$3) -> 0 | E7: =SUM(B7:D7) -> 2
A8: Functions and graphs | B8: =COUNTIFS(Misconceptions!$B$2:$B$34,$A8,Misconceptions!$K$2:$K$34,B$3) -> 1 | C8: =COUNTIFS(Misconceptions!$B$2:$B$34,$A8,Misconceptions!$K$2:$K$34,C$3) -> 1 | D8: =COUNTIFS(Misconceptions!$B$2:$B$34,$A8,Misconceptions!$K$2:$K$34,D$3) -> 3 | E8: =SUM(B8:D8) -> 5
A9: Probability | B9: =COUNTIFS(Misconceptions!$B$2:$B$34,$A9,Misconceptions!$K$2:$K$34,B$3) -> 0 | C9: =COUNTIFS(Misconceptions!$B$2:$B$34,$A9,Misconceptions!$K$2:$K$34,C$3) -> 2 | D9: =COUNTIFS(Misconceptions!$B$2:$B$34,$A9,Misconceptions!$K$2:$K$34,D$3) -> 0 | E9: =SUM(B9:D9) -> 2
A10: Total | B10: =SUM(B4:B9) -> 11 | C10: =SUM(C4:C9) -> 16 | D10: =SUM(D4:D9) -> 6 | E10: =SUM(E4:E9) -> 33
A12: Check: rows on Misconceptions sheet | E12: =COUNTA(Misconceptions!$A$2:$A$34) -> 33
A13: Check: total matches | E13: =IF(E10=E12,"OK","CHECK") -> OK
A15: Note: 'Proportion and geometry' holds scaling and area/perimeter items; 'Geometry' holds shape-definition items.

Sheet Item bank template
A1: Item ID | B1: Misconception ID | C1: Misconception (auto) | D1: Stem (Finnish) | E1: Correct answer | F1: Distractor A (targets the misconception) | G1: Distractor B | H1: Distractor C | I1: Finnish curriculum item | J1: Status | K1: Reviewer | L1: Notes
A2: ITM-001 | B2: ALG-06 | C2: =IFERROR(INDEX(Misconceptions!$D$2:$D$34,MATCH($B2,Misconceptions!$A$2:$A$34,0)),"") -> Operational reading of '=' | D2: Täytä laatikko: 8 + 4 = □ + 5 | E2: 7 | F2: 12 | G2: 17 | H2: 4 | I2: (fill in from curriculum) | J2: Draft | K2: (name) | L2: EXAMPLE ROW: replace or delete. Distractor A is the operational-'=' answer.
C3: =IF($B3="","",IFERROR(INDEX(Misconceptions!$D$2:$D$34,MATCH($B3,Misconceptions!$A$2:$A$34,0)),"ID not found"))
C4: =IF($B4="","",IFERROR(INDEX(Misconceptions!$D$2:$D$34,MATCH($B4,Misconceptions!$A$2:$A$34,0)),"ID not found"))
C5: =IF($B5="","",IFERROR(INDEX(Misconceptions!$D$2:$D$34,MATCH($B5,Misconceptions!$A$2:$A$34,0)),"ID not found"))
C6: =IF($B6="","",IFERROR(INDEX(Misconceptions!$D$2:$D$34,MATCH($B6,Misconceptions!$A$2:$A$34,0)),"ID not found"))
C7: =IF($B7="","",IFERROR(INDEX(Misconceptions!$D$2:$D$34,MATCH($B7,Misconceptions!$A$2:$A$34,0)),"ID not found"))
C8: =IF($B8="","",IFERROR(INDEX(Misconceptions!$D$2:$D$34,MATCH($B8,Misconceptions!$A$2:$A$34,0)),"ID not found"))
C9: =IF($B9="","",IFERROR(INDEX(Misconceptions!$D$2:$D$34,MATCH($B9,Misconceptions!$A$2:$A$34,0)),"ID not found"))
C10: =IF($B10="","",IFERROR(INDEX(Misconceptions!$D$2:$D$34,MATCH($B10,Misconceptions!$A$2:$A$34,0)),"ID not found"))
C11: =IF($B11="","",IFERROR(INDEX(Misconceptions!$D$2:$D$34,MATCH($B11,Misconceptions!$A$2:$A$34,0)),"ID not found"))
C12: =IF($B12="","",IFERROR(INDEX(Misconceptions!$D$2:$D$34,MATCH($B12,Misconceptions!$A$2:$A$34,0)),"ID not found"))
C13: =IF($B13="","",IFERROR(INDEX(Misconceptions!$D$2:$D$34,MATCH($B13,Misconceptions!$A$2:$A$34,0)),"ID not found"))
C14: =IF($B14="","",IFERROR(INDEX(Misconceptions!$D$2:$D$34,MATCH($B14,Misconceptions!$A$2:$A$34,0)),"ID not found"))
... C41: =IF($B41="","",IFERROR(INDEX(Misconceptions!$D$2:$D$34,MATCH($B41,Misconceptions!$A$2:$A$34,0)),"ID not found"))
A43: Legend: yellow cells with blue text are for you to fill. Column C is a formula and fills itself when you choose a misconception ID in column B. Row 2 is an example row.

Sheet Sources
A1: Key | B1: Short citation | C1: Title | D1: Venue and details | E1: DOI / note | F1: Cited by (count of misconception rows)
A2: awawdehshahbari2021cognitive | B2: Awawdeh Shahbari (2021) | C2: Cognitive Conflict in Technological Environment: Cognitive Process and Emotions through Intuitive Errors in Area, Perimeter and Volume | D2: Mathematics, 9(14), 1672 | E2: https://doi.org/10.3390/math9141672 | F2: =COUNTIF(Misconceptions!$L$2:$L$34,"*"&A2&"*") -> 1
A3: beichner1994testing | B3: Beichner (1994) | C3: Testing Student Interpretation of Kinematics Graphs | D3: American Journal of Physics, 62(8), 750–762 | E3: https://doi.org/10.1119/1.17449 | F3: =COUNTIF(Misconceptions!$L$2:$L$34,"*"&A3&"*") -> 2
A4: booth2014persistent | B4: Booth et al. (2014) | C4: Persistent and Pernicious Errors in Algebraic Problem Solving | D4: Journal of Problem Solving, 7(1), 10–23 | E4: https://doi.org/10.7771/1932-6246.1161 | F4: =COUNTIF(Misconceptions!$L$2:$L$34,"*"&A4&"*") -> 1
A5: bush2013prerequisite | B5: Bush & Karp (2013) | C5: Prerequisite Algebra Skills and Associated Misconceptions of Middle Grade Students: A Review | D5: The Journal of Mathematical Behavior, 32(3), 613–632 | E5: https://doi.org/10.1016/j.jmathb.2013.07.002 | F5: =COUNTIF(Misconceptions!$L$2:$L$34,"*"&A5&"*") -> 3
A6: clement1981translation | B6: Clement et al. (1981) | C6: Translation Difficulties in Learning Mathematics | D6: The American Mathematical Monthly, 88(4), 286–290 | E6: https://doi.org/10.2307/2320560 | F6: =COUNTIF(Misconceptions!$L$2:$L$34,"*"&A6&"*") -> 1
A7: clement1982algebra | B7: Clement (1982) | C7: Algebra Word Problem Solutions: Thought Processes Underlying a Common Misconception | D7: Journal for Research in Mathematics Education, 13(1), 16–30 | E7: https://doi.org/10.2307/748434 | F7: =COUNTIF(Misconceptions!$L$2:$L$34,"*"&A7&"*") -> 1
A8: clement1985misconceptions | B8: Clement (1985) | C8: Misconceptions in Graphing | D8: In Proceedings of the Ninth International Conference for the Psychology of Mathematics Education, ed. Streefland, vol. 1, 369–375 | F8: =COUNTIF(Misconceptions!$L$2:$L$34,"*"&A8&"*") -> 2
A9: debock2002improper | B9: De Bock et al. (2002) | C9: Improper Use of Linear Reasoning: An In-Depth Study of the Nature and the Irresistibility of Secondary School Students' Errors | D9: Educational Studies in Mathematics, 50(3), 311–334 | E9: https://doi.org/10.1023/A:1021205413749 | F9: =COUNTIF(Misconceptions!$L$2:$L$34,"*"&A9&"*") -> 3
A10: fischbein1997evolution | B10: Fischbein & Schnarch (1997) | C10: The Evolution with Age of Probabilistic, Intuitively Based Misconceptions | D10: Journal for Research in Mathematics Education, 28(1), 96–105 | F10: =COUNTIF(Misconceptions!$L$2:$L$34,"*"&A10&"*") -> 1
A11: fujita2007learners | B11: Fujita & Jones (2007) | C11: Learners' Understanding of the Definitions and Hierarchical Classification of Quadrilaterals: Towards a Theoretical Framing | D11: Research in Mathematics Education, 9(1--2), 3–20 | E11: https://doi.org/10.1080/14794800008520167 | F11: =COUNTIF(Misconceptions!$L$2:$L$34,"*"&A11&"*") -> 2
A12: fujita2012learners | B12: Fujita (2012) | C12: Learners' Level of Understanding of the Inclusion Relations of Quadrilaterals and Prototype Phenomenon | D12: The Journal of Mathematical Behavior, 31(1), 60–72 | E12: https://doi.org/10.1016/j.jmathb.2011.08.003 | F12: =COUNTIF(Misconceptions!$L$2:$L$34,"*"&A12&"*") -> 1
A13: heinze2002quadrat | B13: Heinze (2002) | C13: “… aber ein Quadrat ist kein Rechteck” – Schülerschwierigkeiten beim Verwenden einfacher geometrischer Begriffe in Jahrgang 8 | D13: Zentralblatt für Didaktik der Mathematik, 34(2), 51–55 | E13: https://doi.org/10.1007/BF02655704 | F13: =COUNTIF(Misconceptions!$L$2:$L$34,"*"&A13&"*") -> 1
A14: joutsenlahti2024percentage | B14: Joutsenlahti & Perkkilä (2024) | C14: Mastery of the Concept of Percentage and Its Representations in Finnish Comprehensive School Grades 7–9 | D14: Education Sciences, 14(10), 1043 | E14: https://doi.org/10.3390/educsci14101043 | F14: =COUNTIF(Misconceptions!$L$2:$L$34,"*"&A14&"*") -> 2
A15: kieran1981equality | B15: Kieran (1981) | C15: Concepts Associated with the Equality Symbol | D15: Educational Studies in Mathematics, 12(3), 317–326 | E15: https://doi.org/10.1007/BF00311062 | F15: =COUNTIF(Misconceptions!$L$2:$L$34,"*"&A15&"*") -> 1
A16: kieran2007learning | B16: Kieran (2007) | C16: Learning and Teaching Algebra at the Middle School through College Levels: Building Meaning for Symbols and Their Manipulation | D16: In Second Handbook of Research on Mathematics Teaching and Learning, ed. Lester, 707–762 | F16: =COUNTIF(Misconceptions!$L$2:$L$34,"*"&A16&"*") -> 1
A17: klingbeil2025omnipresence | B17: Klingbeil & Moons (2025) | C17: The Omnipresence of the Letter-as-Object Misconception: A Multilevel Latent Transition Analysis on Understanding Variables | D17: Educational Studies in Mathematics, 120(3), 455–476 | E17: https://doi.org/10.1007/s10649-025-10428-7 | F17: =COUNTIF(Misconceptions!$L$2:$L$34,"*"&A17&"*") -> 1
A18: knuth2006equal | B18: Knuth et al. (2006) | C18: Does Understanding the Equal Sign Matter? Evidence from Solving Equations | D18: Journal for Research in Mathematics Education, 37(4), 297–312 | F18: =COUNTIF(Misconceptions!$L$2:$L$34,"*"&A18&"*") -> 1
A19: kuchemann1981algebra | B19: Küchemann (1981) | C19: Algebra | D19: In Children's Understanding of Mathematics: 11–16, ed. Hart, 102–119 | F19: =COUNTIF(Misconceptions!$L$2:$L$34,"*"&A19&"*") -> 4
A20: leinhardt1990functions | B20: Leinhardt et al. (1990) | C20: Functions, Graphs, and Graphing: Tasks, Learning, and Teaching | D20: Review of Educational Research, 60(1), 1–64 | F20: =COUNTIF(Misconceptions!$L$2:$L$34,"*"&A20&"*") -> 2
A21: macgregor1997notation | B21: MacGregor & Stacey (1997) | C21: Students' Understanding of Algebraic Notation: 11–15 | D21: Educational Studies in Mathematics, 33(1), 1–19 | E21: https://doi.org/10.1023/A:1002970913563 | F21: =COUNTIF(Misconceptions!$L$2:$L$34,"*"&A21&"*") -> 4
A22: matz1982process | B22: Matz (1982) | C22: Towards a Process Model for High School Algebra Errors | D22: In Intelligent Tutoring Systems, ed. Sleeman; Brown, 25–50 | F22: =COUNTIF(Misconceptions!$L$2:$L$34,"*"&A22&"*") -> 2
A23: merenluoto2004number | B23: Merenluoto & Lehtinen (2004) | C23: Number Concept and Conceptual Change: Towards a Systemic Model of the Processes of Change | D23: Learning and Instruction, 14(5), 519–534 | E23: https://doi.org/10.1016/j.learninstruc.2004.06.016 | F23: =COUNTIF(Misconceptions!$L$2:$L$34,"*"&A23&"*") -> 1
A24: ni2005whole | B24: Ni & Zhou (2005) | C24: Teaching and Learning Fraction and Rational Numbers: The Origins and Implications of Whole Number Bias | D24: Educational Psychologist, 40(1), 27–52 | E24: https://doi.org/10.1207/s15326985ep4001_3 | F24: =COUNTIF(Misconceptions!$L$2:$L$34,"*"&A24&"*") -> 1
A25: planinic2012comparison | B25: Planinić et al. (2012) | C25: Comparison of Student Understanding of Line Graph Slope in Physics and Mathematics | D25: International Journal of Science and Mathematics Education, 10(6), 1393–1414 | E25: https://doi.org/10.1007/s10763-012-9344-1 | F25: =COUNTIF(Misconceptions!$L$2:$L$34,"*"&A25&"*") -> 1
A26: shahbari2015resolving | B26: Awawdeh Shahbari & Peled (2015) | C26: Resolving Cognitive Conflict in a Realistic Situation with Modeling Characteristics: Coping with a Changing Reference in Fractions | D26: International Journal of Science and Mathematics Education, 13(4), 891–907 | E26: https://doi.org/10.1007/s10763-014-9509-1 | F26: =COUNTIF(Misconceptions!$L$2:$L$34,"*"&A26&"*") -> 1
A27: siegler2015conceptual | B27: Siegler & Lortie-Forgues (2015) | C27: Conceptual Knowledge of Fraction Arithmetic | D27: Journal of Educational Psychology, 107(3), 909–918 | E27: https://doi.org/10.1037/edu0000025 | F27: =COUNTIF(Misconceptions!$L$2:$L$34,"*"&A27&"*") -> 2
A28: siegler2017hard | B28: Siegler & Lortie-Forgues (2017) | C28: Hard Lessons: Why Rational Number Arithmetic Is So Difficult for So Many People | D28: Current Directions in Psychological Science, 26(4), 346–351 | E28: https://doi.org/10.1177/0963721417700129 | F28: =COUNTIF(Misconceptions!$L$2:$L$34,"*"&A28&"*") -> 3
A29: silfverberg1999geometrisen | B29: Silfverberg (1999) | C29: Peruskoulun yläasteen oppilaan geometrinen käsitetieto | D29: University of Tampere (doctoral thesis) | E29: https://trepo.tuni.fi/bitstream/handle/10024/66665/951-44-4718-2.pdf?sequence=1 | Note: Acta Electronica Universitatis Tamperensis 6; ISBN 951-44-4718-2; includes an English summary. | F29: =COUNTIF(Misconceptions!$L$2:$L$34,"*"&A29&"*") -> 1
A30: silfverberg2019geometrical | B30: Silfverberg (2019) | C30: Geometrical Conceptualization | D30: In International Handbook of Mathematical Learning Difficulties: From the Laboratory to the Classroom, ed. Fritz; Haase; Räsänen, 611–630 | E30: https://doi.org/10.1007/978-3-319-97148-3_36 | F30: =COUNTIF(Misconceptions!$L$2:$L$34,"*"&A30&"*") -> 1
A31: stavy2000how | B31: Stavy & Tirosh (2000) | C31: How Students (Mis-)Understand Science and Mathematics: Intuitive Rules | D31: Teachers College Press | F31: =COUNTIF(Misconceptions!$L$2:$L$34,"*"&A31&"*") -> 3
A32: steinle2004changes | B32: Steinle (2004) | C32: Changes with Age in Students' Misconceptions of Decimal Numbers | D32: University of Melbourne (doctoral thesis) | F32: =COUNTIF(Misconceptions!$L$2:$L$34,"*"&A32&"*") -> 1
A33: steinle2004longitudinal | B33: Steinle & Stacey (2004) | C33: A Longitudinal Study of Students' Understanding of Decimal Notation: An Overview and Refined Results | D33: In Mathematics Education for the Third Millennium: Towards 2010. Proceedings of the 27th Annual Conference of the Mathematics Education Research Group of Australasia, ed. Putt; Faragher; McLean, vol. 2, 541–548 | F33: =COUNTIF(Misconceptions!$L$2:$L$34,"*"&A33&"*") -> 2
A34: steinle2004persistence | B34: Steinle & Stacey (2004) | C34: Persistence of Decimal Misconceptions and Readiness to Move to Expertise | D34: In Proceedings of the 28th Conference of the International Group for the Psychology of Mathematics Education, ed. Høines; Fuglestad, vol. 4, 225–232 | F34: =COUNTIF(Misconceptions!$L$2:$L$34,"*"&A34&"*") -> 2
A35: tirosh1999intuitive | B35: Tirosh & Stavy (1999) | C35: Intuitive Rules: A Way to Explain and Predict Students' Reasoning | D35: Educational Studies in Mathematics, 38, 51–66 | E35: https://doi.org/10.1023/A:1003436313032 | F35: =COUNTIF(Misconceptions!$L$2:$L$34,"*"&A35&"*") -> 3
A36: vamvakoussi2010many | B36: Vamvakoussi & Vosniadou (2010) | C36: How Many Decimals Are There between Two Fractions? Aspects of Secondary School Students' Understanding of Rational Numbers and Their Notation | D36: Cognition and Instruction, 28(2), 181–209 | E36: https://doi.org/10.1080/07370001003676603 | F36: =COUNTIF(Misconceptions!$L$2:$L$34,"*"&A36&"*") -> 1
A37: vandooren2008linear | B37: Van Dooren et al. (2008) | C37: The Linear Imperative: An Inventory and Conceptual Analysis of Students' Overuse of Linearity | D37: Journal for Research in Mathematics Education, 39(3), 311–342 | F37: =COUNTIF(Misconceptions!$L$2:$L$34,"*"&A37&"*") -> 3
A38: vanhoof2015inappropriately | B38: Van Hoof et al. (2015) | C38: Inappropriately Applying Natural Number Properties in Rational Number Tasks: Characterizing the Development of the Natural Number Bias through Primary and Secondary Education | D38: Educational Studies in Mathematics, 90(1), 39–56 | E38: https://doi.org/10.1007/s10649-015-9613-3 | F38: =COUNTIF(Misconceptions!$L$2:$L$34,"*"&A38&"*") -> 1
A39: vinner1989images | B39: Vinner & Dreyfus (1989) | C39: Images and Definitions for the Concept of Function | D39: Journal for Research in Mathematics Education, 20(4), 356–366 | F39: =COUNTIF(Misconceptions!$L$2:$L$34,"*"&A39&"*") -> 1
A40: vlassis2004minus | B40: Vlassis (2004) | C40: Making Sense of the Minus Sign or Becoming Flexible in “Negativity” | D40: Learning and Instruction, 14(5), 469–484 | E40: https://doi.org/10.1016/j.learninstruc.2004.06.012 | F40: =COUNTIF(Misconceptions!$L$2:$L$34,"*"&A40&"*") -> 2
...
